<mujoco model="z1_description">
    <compiler angle="radian" meshdir="../meshes/" />
    <size njmax="500" nconmax="100" />
<option gravity='0 0 -9.806' iterations='50' solver='Newton' timestep='0.002'/>

<default>
    <geom contype="1" conaffinity="1" friction="0.6 0.3 0.3" rgba="0.5 0.6 0.7 1" margin="0.001" group="0"/>

    <light castshadow="false" diffuse="1 1 1"/>
    <motor ctrlrange="-33.5 33.5" ctrllimited="true"/>
    <camera fovy="60"/>
    <joint damping="0.01" armature="0.01"/>

</default>
    <asset>
        <mesh name="z1_Link00" file="z1_Link00.stl" />
        <mesh name="z1_Link01" file="z1_Link01.stl" />
        <mesh name="z1_Link02" file="z1_Link02.stl" />
        <mesh name="z1_Link03" file="z1_Link03.stl" />
        <mesh name="z1_Link04" file="z1_Link04.stl" />
        <mesh name="z1_Link05" file="z1_Link05.stl" />
        <mesh name="z1_Link06" file="z1_Link06.stl" />
    </asset>
<asset>
    <texture type="skybox" builtin="gradient" rgb1="1.0 1.0 1.0" rgb2="1.0 1.0 1.0" width="512" height="512"/>
    <texture name="plane" type="2d" builtin="flat" rgb1="1 1 1" rgb2="1 1 1" width="512" height="512" mark="cross" markrgb="0 0 0"/>
    <material name="plane" reflectance="0.0" texture="plane" texrepeat="3 3" texuniform="true"/>
</asset>
    <worldbody>
    <light directional="true" diffuse=".8 .8 .8" pos="0 0 10" dir="0 0 -10"/>
<camera name="track" mode="trackcom" pos="0 -1.3 1.6" xyaxes="1 0 0 0 0.707 0.707"/>
<geom name='floor' type='plane' conaffinity='1' condim='3' contype='1' rgba="0.5 0.9 0.9 0.1" material='plane' pos='0 0 0' size='0 0 1'/>
    
        <geom type="mesh" contype="0" conaffinity="0" group="1" mesh="z1_Link00" />
        <geom size="0.0325 0.0255" pos="0 0 0.0255" type="cylinder" />
        <body name="link01" pos="0 0 0.0585">
            <inertial pos="2.47e-06 -0.00025198 0.0231717" quat="0.705633 0.708578 -0.000280458 0.000356448" mass="0.673326" diaginertia="0.00128328 0.000839362 0.000719308" />
            <joint name="joint1" pos="0 0 0" axis="0 0 1" limited="true" range="-2.61799 2.61799" damping="1" frictionloss="1" />
            <geom type="mesh" contype="0" conaffinity="0" group="1" mesh="z1_Link01" />
            <body name="link02" pos="0 0 0.045">
                <inertial pos="-0.110126 0.00240029 0.00158266" quat="-0.00720473 0.706934 0.0117222 0.707146" mass="1.19132" diaginertia="0.0246612 0.0243113 0.00100468" />
                <joint name="joint2" pos="0 0 0" axis="0 1 0" limited="true" range="0 3.14159" damping="2" frictionloss="2" />
                <geom type="mesh" contype="0" conaffinity="0" group="1" mesh="z1_Link02" />
                <geom size="0.0325 0.051" quat="0.707107 0.707107 0 0" type="cylinder" />
                <geom size="0.0225 0.1175" pos="-0.1625 0 0" quat="0.707107 0 0.707107 0" type="cylinder" />
                <geom size="0.0325 0.0255" pos="-0.35 0 0" quat="0.707107 0.707107 0 0" type="cylinder" />
                <body name="link03" pos="-0.35 0 0">
                    <inertial pos="0.106092 -0.00541815 0.0347638" quat="0.390759 0.613535 0.495032 0.475211" mass="0.839409" diaginertia="0.00955021 0.00938044 0.000558553" />
                    <joint name="joint3" pos="0 0 0" axis="0 1 0" limited="true" range="-4.7822 0" damping="1" frictionloss="1" />
                    <geom type="mesh" contype="0" conaffinity="0" group="1" mesh="z1_Link03" />
                    <geom size="0.02 0.058" pos="0.128 0 0.055" quat="0.707107 0 0.707107 0" type="cylinder" />
                    <geom size="0.0325 0.0295" pos="0.2205 0 0.055" quat="0.707107 0 0.707107 0" type="cylinder" />
                    <body name="link04" pos="0.218 0 0.057">
                        <inertial pos="0.0436668 0.00364738 -0.00170192" quat="0.0441445 0.67379 0.128937 0.726246" mass="0.564046" diaginertia="0.000984312 0.00093769 0.000302838" />
                        <joint name="joint4" pos="0 0 0" axis="0 1 0" limited="true" range="-1.74533 1.5708" damping="1" frictionloss="1" />
                        <geom type="mesh" contype="0" conaffinity="0" group="1" mesh="z1_Link04" />
                        <geom size="0.0325 0.0365" pos="0.0472 0 0" quat="0.707107 0.707107 0 0" type="cylinder" />
                        <body name="link05" pos="0.07 0 0">
                            <inertial pos="0.0312153 0 0.00646316" quat="0.531936 0.464048 0.457086 0.541088" mass="0.389385" diaginertia="0.000558963 0.000547314 0.000167332" />
                            <joint name="joint5" pos="0 0 0" axis="0 0 1" limited="true" range="-1.72788 1.72788" damping="1" frictionloss="1" />
                            <geom type="mesh" contype="0" conaffinity="0" group="1" mesh="z1_Link05" />
                            <body name="link06" pos="0.0492 0 0">
                                <inertial pos="0.0241569 -0.00017355 -0.00143876" quat="0.997266 -0.0715433 0.00854786 -0.0164304" mass="0.288758" diaginertia="0.000183329 0.000147473 0.000146778" />
                                <joint name="joint6" pos="0 0 0" axis="1 0 0" limited="true" range="-2.79253 2.79253" damping="1" frictionloss="1" />
                                <geom type="mesh" contype="0" conaffinity="0" group="1" mesh="z1_Link06" />
                                <geom size="0.0325 0.0255" pos="0.0255 0 0" quat="0.707107 0 0.707107 0" type="cylinder" />
                            </body>
                        </body>
                    </body>
                </body>
            </body>
        </body>
    </worldbody>
    <actuator>
    <motor name="joint1_motor" joint="joint1" />
    <motor name="joint2_motor" joint="joint2" />
    <motor name="joint3_motor" joint="joint3" />
    <motor name="joint4_motor" joint="joint4" />
    <motor name="joint5_motor" joint="joint5" />
    <motor name="joint6_motor" joint="joint6" />
    </actuator>
</mujoco>
